Workbook

Sheet Özet
A1: Modül | B1: Kalem sayısı | C1: Fiyatı bilinmeyen | D1: Toplam (TL, KDV dahil)
A2: 1 Pozlama | B2: =COUNTIF(BOM!B2:B80,A2) | C2: =COUNTIFS(BOM!B2:B80,A2,BOM!G2:G80,"") | D2: =SUMIF(BOM!B2:B80,A2,BOM!H2:H80)
A3: 2 CNC portal | B3: =COUNTIF(BOM!B2:B80,A3) | C3: =COUNTIFS(BOM!B2:B80,A3,BOM!G2:G80,"") | D3: =SUMIF(BOM!B2:B80,A3,BOM!H2:H80)
A4: 3 Islak istasyon | B4: =COUNTIF(BOM!B2:B80,A4) | C4: =COUNTIFS(BOM!B2:B80,A4,BOM!G2:G80,"") | D4: =SUMIF(BOM!B2:B80,A4,BOM!H2:H80)
A5: 4 Hot plate | B5: =COUNTIF(BOM!B2:B80,A5) | C5: =COUNTIFS(BOM!B2:B80,A5,BOM!G2:G80,"") | D5: =SUMIF(BOM!B2:B80,A5,BOM!H2:H80)
A6: 5 Elektronik | B6: =COUNTIF(BOM!B2:B80,A6) | C6: =COUNTIFS(BOM!B2:B80,A6,BOM!G2:G80,"") | D6: =SUMIF(BOM!B2:B80,A6,BOM!H2:H80)
A7: TOPLAM | B7: =SUM(B2:B6) | C7: =SUM(C2:C6) | D7: =SUM(D2:D6)
A9: PCB üretim makinesi, prototip v0. Fiyatlar 2026-10-04, Türkiye satıcıları. Kaynak: bom_v0.py
A10: CNC: ana liste özel yapım (ray + bilyalı vida). Hazır kitler "Alternatifler" sayfasında.

Sheet Kesim karşılaştırma
A1: Yöntem | B1: Örnek makine | C1: Fiyat (TL) | D1: Fiyat notu | E1: Link | F1: FR4 kesim | G1: Delik | H1: Bakır işleme | I1: Dezavantaj | J1: Karar
A2: CNC freze (ER11 mil) | B2: Kendi yapım portal (bu BOM, CNC modülü) | C2: 37854.21 | D2: BOM toplamı (pim, plaka hariç) | F2: Temiz: 1,6–2,4 mm mısır koçanı freze | G2: Evet, 0,3–3 mm, düz ve temiz | H2: İzolasyon frezesi yapılabilir (yavaş) | I2: Cam elyaf tozu: vakum/emiş şart; uç aşınması (sarf) | J2: SEÇİLEN: kesim + delme
A3: CNC freze (hazır kit) | B3: CNC3018 lazerli kit (775 mil, T-vida, ±0,1 mm) | C3: 26700 | D3: Motorobit, stokta | E3: https://www.motorobit.com/cnc3018-15000mw-lazerli-cnc-makinesi-kesim-tezga | F3: Temiz, ama salgı ve boşluk yüksek | G3: Evet; 0,6 mm altı uç kırılır | H3: Sınırlı | I3: GRBL (GPL), ±0,1 mm | J3: Yalnız v0 denemesi
A4: CNC freze (hazır, rayli) | B4: DRNC 3025 (bilyalı vida + 15 mm ray, 600 W ER11) | C4: 104611.61 | D4: Direnc, stokta (1) | E4: https://www.direnc.net/drnc-3025-masaustu-cnc-ve-lazer-makinesi | F4: Temiz | G4: Evet | H4: Evet | I4: Pahalı; kapalı yazılım ürüne girmez | J4: Referans/ölçüm makinesi olabilir
A5: Diyot lazer 10–40 W (455 nm) | B5: Creality Falcon A1 10 W / Falcon2 Pro 40 W | C5: 28382.64 | D5: 10 W Robotistan stokta; 40 W 85.147,91 | E5: https://www.robotistan.com/creality-falcon-a1-lazer-gravur-ve-kesici-10w | F5: HAYIR: cam elyaf mavi ışığı emmez, epoksi kömürleşir | G5: Hayır | H5: Bakıra işlemez; boya/lak maskesi yakılabilir (boya+lazer+aşındırma) | I5: FR4 yanınca bromlu zehirli duman | J5: Kesim için uygun değil
A6: CO2 lazer 40–55 W (10,6 µm) | B6: K40 tipi 40 W (ABP/Xenon) … xTool P2S 55 W | D6: 900–2.350 $ + KDV (K40); P2S 239–463 bin TL | E6: https://www.makinaturkiye.com/40w-co2-lazer-kase-makinesi-p-172299 | F6: Kötü: kenar kömürleşir (iletken olabilir), cam erir | G6: Kötü (konik, kömürlü) | H6: Hayır: bakır 10,6 µm'yi yansıtır | I6: Zehirli duman, kenar kalitesi | J6: Uygun değil
A7: Fiber lazer 20–50 W (1064 nm, galvo) | B7: Roboyek 20 W Raycus, 300x300 mm | C7: 122000 | D7: 30 W 150.000; 50 W 190.000 (KDV belirtilmemiş) | E7: https://roboyek.com/urun/roboyek-20w-fiber-lazer-markalama-makinasi/ | F7: Çok paso ile mümkün ama yavaş ve kömürlü | G7: Zor (çok paso, konik) | H7: EVET: bakırı doğrudan söker (kimyasalsız izolasyon) | I7: Pahalı, Sınıf 4, duman filtresi, galvo alanı sınırlı | J7: v2: kimyasalsız izolasyon için değerlendirilebilir
A8: UV lazer 5 W (355 nm) | B8: Ayka JPT 5 W, 100x100 mm | C8: 382653.96 | D8: KDV dahil, stokta | E8: https://www.aykalazer.com/uv-lazer-markalama-makinasi-jpt-5w-ada | F8: Temiz ("soğuk" kesim), ama 1,6 mm'de yavaş | G8: İnce mikro-delik iyi; büyük delik yavaş | H8: Evet, en temiz | I8: Çok pahalı; sanayide ayırma (depaneling) için | J8: Ürün maliyetine uymaz
A9: 405 nm düşük güç lazer (pozlama) | B9: KALE 300 mW 405 nm modül | C9: 7476.47 | D9: Grup Elektronik, 1 adet | E9: https://www.grupelektronik.com/urun/300mw-405nm-mor-otesi-ultraviole | F9: Hayır | G9: Hayır | H9: Yalnız lak/dry film pozlar (doğrudan lazer pozlama) | I9: Yavaş tarama | J9: LCD yolunun yedeği

Sheet Delme makinesi v0
A1: Kalem | B1: Özellik | C1: Adet | D1: Birim fiyat (TL) | E1: Toplam (TL) | F1: Satıcı | G1: Link | H1: Stok | I1: Doğrulandı | J1: Not
A2: 28BYJ-48 5 V + ULN2003 | B2: X, Y, Z eksenleri | C2: 3 | D2: 54.05 | E2: =IF(D2="","",C2*D2) | F2: RobitShop | G2: https://www.robitshop.com/urun/28-byj-48-reduktorlu-step-motor-ve-uln2003-step-motor-surucu-karti-mavi | H2: Var (397) | I2: evet | J2: Alt.: Direnc 92,99, Robotistan 100,98. 12 V sürümü TR'de yok.
A3: LM8UU | B3: 8 mm lineer rulman (X 4, Y 4, Z 4) | C3: 12 | D3: 42 | E3: =IF(D3="","",C3*D3) | F3: Motorobit | G3: https://www.motorobit.com/3d-yazici-icin-rulman-lm8uu | H3: Var (75) | I3: evet
A4: Krom mil Ø8, 300 mm | B4: Kes: X 2x262, Y 2x250, Z 2x110 (bir milden) | C4: 5 | D4: 138 | E4: =IF(D4="","",C4*D4) | F4: Motorobit | G4: https://www.motorobit.com/8mm-induksiyonlu-mil-krom-kapli-300mm | H4: Var (26) | I4: evet | J4: 250/330 mm TR'de yok. Sertleştirilmiş mil taşla (avuç taşlama) kesilir; yerel lineer rulmancıda kestirmek daha ucuz olabilir.
A5: GT2 kayış 6 mm, 2 m | B5: X 620 + Y 596 mm | C5: 1 | D5: 116.24 | E5: =IF(D5="","",C5*D5) | F5: Direnc.net | G5: https://www.direnc.net/gt2-zamanlama-kayisi-6mm-2-metre | H5: Var (22) | I5: evet | J5: 1 m yetmez.
A6: GT2 dişsiz rulmanlı avara (3 mm) | B6: Hazır avara; baskı avara yerine | C6: 2 | D6: 66 | E6: =IF(D6="","",C6*D6) | F6: Motorobit | G6: https://www.motorobit.com/gt2-dissiz-3mm-rulmanli-kasnak | H6: Var (524) | I6: evet | J6: 623ZZ TR'de bulunamadı (624ZZ baskı avaraya sığmaz). Baskı kasnaklar yine 28BYJ miline (D 5/3 mm).
A7: RS775 DC motor, 5 mm mil | B7: 12–36 V, rulmanlı, "3000 rpm" | C7: 1 | D7: 270.22 | E7: =IF(D7="","",C7*D7) | F7: RobitShop | G7: https://www.robitshop.com/urun/rs775-dc-motor-rulmanli-12v-3000-rpm-sarjli-matkap-motoru | H7: Var (12) | I7: evet | J7: PCB için devir düşük (karbür ~10.000 rpm sever): yavaş ilerle ya da daha hızlı 775 bul (pazaryeri, doğrulanmadı). TR'de bulunan tek 5 mm milli 12 V 775.
A8: Mandren / pens seti 5 mm mil | B8: 10 pens 0,5–3,2 mm (3,175 saplı karbür uçları tutar) | C8: 1 | D8: 318 | E8: =IF(D8="","",C8*D8) | F8: Motorobit | G8: https://www.motorobit.com/el-matkabi-mandren-seti-5mm | H8: Var (45) | I8: evet | J8: JT0 yerine pens tipi. MAN02 (≤3 mm) ve MAN01 (≤2,4 mm mil) uymaz.
A9: T8 trapez mil 400 mm + pirinç somun | B9: T8x8; 150 mm'ye kesilir | C9: 1 | D9: 300 | E9: =IF(D9="","",C9*D9) | F9: Motorobit | G9: https://www.motorobit.com/3d-yazici-vidali-mil-somun-400mm-40-cm-t8-8mm | H9: Var (56) | I9: evet | J9: 100–150 mm TR'de yok. Tork yetmezse T8x2 (4 kat kuvvet, 1/4 hız).
A10: Kaplin 5x8 | B10: Z motoru – T8 | C10: 1 | D10: 45 | E10: =IF(D10="","",C10*D10) | F10: Motorobit | G10: https://www.motorobit.com/aluminyum-sabit-kaplin-5x8mm | H10: Var (100) | I10: evet | J10: Esnek alt.: 84 TL (Motorobit).
A11: Mikro switch | B11: DM1-00P-130G, X/Y/Z sıfırlama | C11: 3 | D11: 4.8 | E11: =IF(D11="","",C11*D11) | F11: Motorobit | G11: https://www.motorobit.com/dm1-00p-130g-mikro-switch | H11: Var | I11: evet
A12: 12 V 3 A adaptör | B12: 5,5 mm jak; spindle + 5 V düşürücü girişi | C12: 1 | D12: 240 | E12: =IF(D12="","",C12*D12) | F12: Motorobit | G12: https://www.motorobit.com/12v-3a-adaptor-gs-p120300e553 | H12: Var (58) | I12: evet
A13: 5 V 3 A düşürücü | B13: LM2596-5V; 3 x 28BYJ ~0,75 A | C13: 1 | D13: 160.14 | E13: =IF(D13="","",C13*D13) | F13: Robotistan | G13: https://www.robotistan.com/5v-3a-voltaj-regulator-karti-lm2596-5v | H13: Var (536) | I13: evet
A14: MOSFET kartı | B14: 15 A PWM, 3,3 V tetik (spindle) | C14: 1 | D14: 93.21 | E14: =IF(D14="","",C14*D14) | F14: Robotistan | G14: https://www.robotistan.com/15a-400w-pwm-kontrollu-mosfet-anahtarlama-karti | H14: Var (174) | I14: evet | J14: + 1N5819 diyot 1,20 TL (Motorobit).
A15: M3/M4 vida + somun | B15: Direnc paketleri (M3 16 mm, M3 somun, M4 16 mm, M4 somun) | C15: 1 | D15: 92 | E15: =IF(D15="","",C15*D15) | F15: Direnc.net | G15: https://www.direnc.net/m3-15mm-ysb-20-adet | H15: Var | I15: hayır | J15: Toplam paket fiyatı, arama verisinden.
A16: PCB karbür uç seti | B16: 0,3–1,2 mm, 10 adet, 3,175 sap | C16: 1 | D16: 270 | E16: =IF(D16="","",C16*D16) | F16: Motorobit | G16: https://www.motorobit.com/pcb-matkap-ucu-seti-03-1 | H16: Var | I16: evet | J16: 0,6 mm altı uçlar salgıya hassas.
A17: ESP32-S3 | B17: Kullanıcıda var | C17: 1 | D17: 0 | E17: =IF(D17="","",C17*D17) | F17: — | H17: — | I17: —
A18: PETG filament | B18: ~300 g (16 parça, %40 doluluk; kaba tahmin) | C18: 1 | E18: =IF(D18="","",C18*D18) | F18: — | H18: — | I18: hayır | J18: Elde varsa 0.
A19: Kontrplak / MDF | B19: Taban 370x357 (18), kolon 160x278, Z plakası 110x175, 2 yanak 105x175 (18), tabla 180x120 (9), lata 220x40 (8), feda 164x104 (3) | C19: 1 | E19: =IF(D19="","",C19*D19) | F19: Yerel kesim | H19: — | I19: hayır | J19: Ölçüler delme/README.md.
A20: Hizalama pimi Ø3 | B20: DIN 6325 3x16 ya da 3 mm gümüş çelik | C20: 2 | E20: =IF(D20="","",C20*D20) | F20: Hırdavat | H20: — | I20: hayır | J20: TR e-ticarette bulunamadı.
A21: TOPLAM | E21: =SUM(E2:E20) | J21: Fiyatsız satırlar hariç; kargo hariç

Sheet BOM
A1: No | B1: Modül | C1: Kalem | D1: Özellik | E1: Adet | F1: Birim | G1: Birim fiyat (TL, KDV dahil) | H1: Toplam (TL) | I1: Satıcı | J1: Link | K1: Stok (2026-10-04) | L1: Doğrulandı | M1: Not / alternatif
A2: 1 | B2: 1 Pozlama | C2: Mono LCD 6.6" 4K (Aptus) | D2: Aptus DBM066M4K01, 4098x2560, 35 µm, aktif alan 143.43x89.60 mm, MIPI 50 pin (master+slave) | E2: 2 | F2: adet | H2: =IF(G2="","",E2*G2) | I2: Aptus Display (Shenzhen, OEM) | J2: https://www.aptusdisplay.com/products/6-6-inch-4k-4098x2560-mono-lcd-display | K2: Numune / teklif | L2: hayır | M2: Kullanıcının seçimi (2026-10-04). Desen ≤143x89 mm; ham plaket 160x100, hizalama pimleri kenarda (delme makinesiyle aynı). Fiyat/MOQ/405 nm geçirgenlik sorulacak.
A3: 2 | B3: 1 Pozlama | C3: HDMI → MIPI sürücü kartı (Aptus) | D3: Aptus panel için özel HDMI-MIPI kart | E3: 2 | F3: adet | H3: =IF(G3="","",E3*G3) | I3: Aptus Display (Shenzhen, OEM) | J3: https://www.aptusdisplay.com/products/6-6-inch-4k-4098x2560-mono-lcd-display | K3: Numune / teklif | L3: hayır | M3: Panel MIPI zamanlamasını çözmeden HDMI ile sürülür (6.6" panel için). Giriş çözünürlüğü/EDID ve mono piksel paketlemesi sorulacak.
A4: 3 | B4: 1 Pozlama | C4: Raspberry Pi 5 8 GB | D4: Panelin HDMI kaynağı (pozlama görüntüsü); ürün için Compute Module 5 | E4: 1 | F4: adet | G4: 12010.34 | H4: =IF(G4="","",E4*G4) | I4: Robotistan | J4: https://www.robotistan.com/raspberry-pi-5-8gb | K4: Stokta | L4: evet | M4: Pi 5 4 GB her yerde tükenmiş (~6.900–8.000 TL). Ürün: CM5 2 GB/16 GB 6.228,05 TL stokta + CM5 IO Board 1.260,79 TL (Robotistan).
A5: 4 | B5: 1 Pozlama | C5: UV LED ışık modülü | D5: Anycubic Photon Mono M7 Pro ışık kartı, 405 nm matris, 10" sınıfı | E5: 1 | F5: adet | G5: 4230 | H5: =IF(G5="","",E5*G5) | I5: 3Dream | J5: https://store.3dream.com.tr/products/anycubic-uv-led-modulu | K5: Stokta | L5: evet | M5: Gerilim/akım sayfada yok: kart etiketinden ölçülmeli. Alt.: Creality Halot Lite/Sky UV light, Robo90 470,40 TL (fiyat şüpheli düşük, teyit et). Gerçek 405 nm COB TR'de yok → Yurt dışı sayfası.
A6: 5 | B6: 1 Pozlama | C6: Fresnel mercek | D6: Anycubic Mono M7 / M7 Pro Fresnel (ışık modülüyle aynı set) | E6: 1 | F6: adet | G6: 1645 | H6: =IF(G6="","",E6*G6) | I6: 3Dream | J6: https://store.3dream.com.tr/products/anycubic-fresnel-lens | K6: Stokta | L6: evet | M6: Alt.: A4 sayfa büyüteci 180x120 PVC, Hepsiburada ~398 TL (doğrulanamadı; odak ve 405 nm geçirgenliği belirsiz).
A7: 6 | B7: 1 Pozlama | C7: LCD koruma filmi | D7: Anycubic M7/M7 Pro ekran koruyucu, 5'li | E7: 1 | F7: paket | G7: 1176 | H7: =IF(G7="","",E7*G7) | I7: Robo90 | J7: https://www.robo90.com/anycubic-ekran-koruyucu-5-adet-mono-m7m7-pro | K7: Stokta | L7: evet | M7: Panel ile kart arası kalınlık bulanıklık yapar: ince koruyucu tercih et. Phrozen 4K'ya ölçü uyumu kontrol edilmeli.
A8: 7 | B8: 1 Pozlama | C8: Sabit akım LED sürücü | D8: XL4015 ekranlı DC-DC, CC+CV, giriş ≤38 V, 5 A | E8: 1 | F8: adet | G8: 418.45 | H8: =IF(G8="","",E8*G8) | I8: Direnc.net | J8: https://www.direnc.net/xl4015-display-dc-dc-power-modul | K8: Stokta | L8: evet | M8: Direnc'in 98,80 TL'lik "XL4015 5A Ayarlanabilir" modülü sabit akım DEĞİL. Ürün için Mean Well LDD-H (PWM kısılabilir) → Yurt dışı.
A9: 8 | B9: 1 Pozlama | C9: COB soğutucu seti | D9: 50 W COB alüminyum soğutucu 90x90x20 mm, LED yuvası 25.5x25.5 mm, vida arası 34 mm (+60° lens + 220 V kablo) | E9: 1 | F9: set | G9: 660 | H9: =IF(G9="","",E9*G9) | I9: Motorobit | J9: https://www.motorobit.com/50w-cob-led-aluminyum-sogutucu-60-derece-lens-kablo-seti | K9: Stokta (10+) | L9: evet | M9: LED ve sürücü YOK. Yalnız soğutucu kullanılır: 60° lens ışığı yayar (paralel ışık gerekir), 220 V kablo sürücüsüz şebeke COB'u içindir. COB, Fresnel odağına konur.
A10: 9 | B10: 1 Pozlama | C10: Fan 92 mm | D10: 92x92x25, 12 V 0,26 A, 3 kablo | E10: 1 | F10: adet | G10: 72 | H10: =IF(G10="","",E10*G10) | I10: Motorobit | J10: https://www.motorobit.com/92x92x25mm-12v-026a-fan-3-kablolu-sari | K10: Stokta | L10: evet | M10: Soğutucuya (90 mm) oturur. Kalite/PWM alt.: NMB 92 mm 4 kablo 420 TL (Motorobit).
A11: 10 | B11: 1 Pozlama | C11: Sıcaklık sensörü (LED) | D11: DS18B20, M10 vidalı prob, 1 m | E11: 1 | F11: adet | G11: 312 | H11: =IF(G11="","",E11*G11) | I11: Motorobit | J11: https://www.motorobit.com/ds18b20-m10-dijital-sicaklik-sensoru-1-metre | K11: Stokta | L11: evet | M11: Ucuz alt.: çıplak DS18B20 36 TL (Motorobit) ya da 10k NTC 6,74 TL (Direnc).
A12: 11 | B12: 1 Pozlama | C12: UV koruma gözlüğü | D12: Univet 5X7.03.00.04, turuncu lens, ~525 nm'ye kadar keser | E12: 1 | F12: adet | G12: 1489.08 | H12: =IF(G12="","",E12*G12) | I12: Koçtaş | J12: https://www.koctas.com.tr/univet-5x7030004-turuncu-lensli-gozluk/p/5000208517 | K12: ? | L12: hayır | M12: LED pozlama için yeterli. Profesyonel alt.: GHP 180–540 nm OD5+, lazergozluk.net 17.650 TL.
A13: 12 | B13: 1 Pozlama | C13: UV engelleyici kapak malzemesi | D13: 3 mm turuncu akrilik (pleksi), ölçüye kesim | E13: 1 | F13: levha | H13: =IF(G13="","",E13*G13) | I13: Hepsiburada (TeknoTrust) | J13: https://www.hepsiburada.com/teknotrust-3-mm-akrilik-pleksi-levha-seffaf-kalinlik-tum-ebatlar-icin-gecerlidir-pm-HBC00008CFKNV | K13: ? | L13: hayır | M13: Sıradan turuncu pleksinin 405 nm'yi kestiği garanti değil, test et. Asıl yol: reçine yazıcı kapağı / UV engelleyici akrilik → Yurt dışı.
A14: 13 | B14: 2 CNC portal | C14: Lineer ray HGR15 | D14: 15 mm, Hiwin uyumlu, metre fiyatı, ücretsiz kesim | E14: 2 | F14: m | G14: 766.51 | H14: =IF(G14="","",E14*G14) | I14: cnc-marketi | J14: https://www.cnc-marketi.com/urun/lineer-kizak-15-mm-lineer-kizak-fiyatlari | K14: Stokta (572 m) | L14: evet | M14: X/Y/Z ikişer ray ~300 mm. Alt.: Rulmansepetim 1.236,27 TL/m. Daha hafif: MGN12 400 mm set, Motorobit 1.080 TL.
A15: 14 | B15: 2 CNC portal | C15: Lineer araba HGH15CA | D15: Dar tip, Hiwin uyumlu | E15: 8 | F15: adet | G15: 389.96 | H15: =IF(G15="","",E15*G15) | I15: cnc-marketi | J15: https://www.cnc-marketi.com/urun/15-mm-dar-lineer-kizak-arabasi-17737367412859 | K15: Stokta | L15: evet | M15: Alt.: Rulmansepetim 431,41 TL.
A16: 15 | B16: 2 CNC portal | C16: Bilyalı vida SFU1204 | D16: Uçları tornalanmış (BK/BF10), somun dahil, 350 mm | E16: 3 | F16: adet | G16: 2525.52 | H16: =IF(G16="","",E16*G16) | I16: ileri3d | J16: https://www.ileri3d.com/urun/sfu-1204-tornalanmis-mil-ve-vidali-somun-350mm | K16: Stokta görünüyor | L16: evet | M16: 250/300 mm tükendi. Haddelenmiş C7 tek somun birkaç 10 µm boşluk taşır: ±0,02 mm için ön yüklü/C5 gerekebilir (Mermak/Rulmansepetim'e sor).
A17: 16 | B17: 2 CNC portal | C17: BK10 sabit yatak | D17: 1204 için | E17: 3 | F17: adet | G17: 313.32 | H17: =IF(G17="","",E17*G17) | I17: cnc-marketi | J17: https://www.cnc-marketi.com/urun/bk-10-vidali-mil-uc-yataklari | K17: Stokta | L17: evet | M17: Alt.: ileri3d 1.036,11 TL.
A18: 17 | B18: 2 CNC portal | C18: BF10 serbest yatak | D18: 8 mm mil | E18: 3 | F18: adet | G18: 201.71 | H18: =IF(G18="","",E18*G18) | I18: cnc-marketi | J18: https://www.cnc-marketi.com/urun/bf-10-vidali-mil-uc-yataklari-8mm | K18: Stokta | L18: evet | M18: Alt.: ileri3d 518,05 TL.
A19: 18 | B19: 2 CNC portal | C19: Somun gövdesi 1204 | E19: 3 | F19: adet | G19: 548.67 | H19: =IF(G19="","",E19*G19) | I19: ileri3d | J19: https://www.ileri3d.com/urun/somun-govdesi | K19: Stokta görünüyor | L19: evet | M19: Alt.: Rhino3D 326,66 TL.
A20: 19 | B20: 2 CNC portal | C20: Kaplin 5x8 | D20: Alüminyum sabit (rijit) | E20: 3 | F20: adet | G20: 45 | H20: =IF(G20="","",E20*G20) | I20: Motorobit | J20: https://www.motorobit.com/aluminyum-sabit-kaplin-5x8mm | K20: Stokta (100) | L20: evet | M20: Esnek/çeneli tercih edilir: cnc-marketi GS14 409,60 TL (5x8 için sor).
A21: 20 | B21: 2 CNC portal | C21: Step motor NEMA17 | D21: 0,47 Nm | E21: 3 | F21: adet | G21: 471.26 | H21: =IF(G21="","",E21*G21) | I21: cnc-marketi | J21: https://www.cnc-marketi.com/urun/0-47-nm-step-motor-nema-17 | K21: Stokta | L21: evet | M21: Alt.: NEMA23 2,2 Nm, Motorobit 1.800 TL.
A22: 21 | B22: 2 CNC portal | C22: Step sürücü TMC5160 | D22: MKS TMC5160 PRO, SPI, dahili rampa üreteci | E22: 3 | F22: adet | G22: 1606.86 | H22: =IF(G22="","",E22*G22) | I22: Rhino3D Printer | J22: https://www.rhino3dprinter.com/urun/mks-tmc5160-pro-step-motor-surucusu | K22: Stokta | L22: evet | M22: Ucuz alt.: TMC2209 V2.0, Motorobit 390 TL (≤29 V, rampa üreteci yok).
A23: 22 | B23: 2 CNC portal | C23: ER11 mil seti | D23: 400 W, 12–48 V, 3–12k rpm, φ52, ER11 + braket + hız sürücüsü | E23: 1 | F23: set | G23: 6900 | H23: =IF(G23="","",E23*G23) | I23: F1Depo | J23: https://www.f1depo.com/urun/0-4-kw-spindle-motor-er11-bracket-tutma-aparati | K23: Belirsiz ("Gelince haber ver") | L23: evet | M23: Stok teyit et. Alt.: Motorobit 200 W 12–48 V mil 2.220 TL + ER11 şaft tutucu 510 TL. Salgı (runout) ölçülmeli.
A24: 23 | B24: 2 CNC portal | C24: Mil güç kaynağı 48 V | D24: 48 V 7,3 A, 350 W | E24: 1 | F24: adet | G24: 1859.76 | H24: =IF(G24="","",E24*G24) | I24: Direnc.net | J24: https://www.direnc.net/24v-165a-metal-switch-mod-adaptor | K24: Stokta | L24: TEYİT ET | M24: Link adı "24V 16.5A" gösteriyor: 48 V model olduğunu siparişten önce teyit et.
A25: 24 | B25: 2 CNC portal | C25: ER11 pens 3,175 mm (1/8") | D25: PCB matkap/freze sapı için | E25: 2 | F25: adet | G25: 150 | H25: =IF(G25="","",E25*G25) | I25: Motorobit | J25: https://www.motorobit.com/er11-3175mm-pens-18 | K25: Stokta (6) | L25: evet | M25: cnc-marketi 7'li sette 3,175 YOK.
A26: 25 | B26: 2 CNC portal | C26: PCB matkap seti | D26: 0,3–1,2 mm, 10 adet, 3,175 mm sap | E26: 2 | F26: set | G26: 270 | H26: =IF(G26="","",E26*G26) | I26: Motorobit | J26: https://www.motorobit.com/pcb-matkap-ucu-seti-03-1 | K26: Stokta (31) | L26: evet | M26: 3 mm pim delikleri için ayrı 3,0 mm karbür matkap gerekir (aranmadı).
A27: 26 | B27: 2 CNC portal | C27: Kenar frezesi | D27: Karbür "elmas/mısır koçanı" 1,6 mm, 3,17 mm sap | E27: 3 | F27: adet | G27: 150 | H27: =IF(G27="","",E27*G27) | I27: Motorobit | J27: https://www.motorobit.com/elmas-freze-matkap-ucu-160mm-x-11mm | K27: Stokta | L27: evet | M27: 1,85/2,05/2,45 mm de var.
A28: 27 | B28: 2 CNC portal | C28: Sigma profil 40x40 | D28: 8 kanal hafif, ücretsiz kesim | E28: 3 | F28: m | G28: 774.84 | H28: =IF(G28="","",E28*G28) | I28: cnc-marketi | J28: https://www.cnc-marketi.com/urun/sigma-profil-40x40-sigma-profil-8-kanal | K28: Stokta (289 m) | L28: evet | M28: Alüminyum plaka (tabla, Z plakası) için yerel lazer/CNC kesimciden teklif.
A29: 28 | B29: 2 CNC portal | C29: Köşe bağlantı 40x40 K8 | D29: Geniş köşe | E29: 16 | F29: adet | G29: 38.51 | H29: =IF(G29="","",E29*G29) | I29: cnc-marketi | J29: https://www.cnc-marketi.com/urun/genis-kose-baglanti-40x40-k8 | K29: Stokta | L29: evet
A30: 29 | B30: 2 CNC portal | C30: T-somun M5 K8 | E30: 100 | F30: adet | G30: 3.67 | H30: =IF(G30="","",E30*G30) | I30: cnc-marketi | J30: https://www.cnc-marketi.com/urun/t-kanal-somunu-m5-30x30-k8 | K30: Stokta | L30: evet
A31: 30 | B31: 2 CNC portal | C31: Endüktif limit sensörü | D31: LJ12A3-4-Z/BX, NPN | E31: 3 | F31: adet | G31: 116.24 | H31: =IF(G31="","",E31*G31) | I31: Direnc.net | J31: https://www.direnc.net/enduktif-npn-proximity-sensor-lj12a3-4-zbx | K31: Stokta (152) | L31: evet | M31: Alt.: mekanik ME-8111, Motorobit 126 TL.
A32: 31 | B32: 2 CNC portal | C32: Takım sıfırlama probu | D32: Yaylı Z probu | E32: 1 | F32: adet | G32: 2358.33 | H32: =IF(G32="","",E32*G32) | I32: Meon Otomasyon | J32: https://www.meonotomasyon.com/urun/cnc-takim-sifirlama-probu | K32: Muhtemelen stokta | L32: evet | M32: Yükseklik haritası için bakır–uç süreklilik probu (iki kablo) da yeter.
A33: 32 | B33: 2 CNC portal | C33: Konum pimi 3 mm | D33: DIN 6325 / ISO 8734, sertleştirilmiş, 3x20 mm | E33: 10 | F33: adet | H33: =IF(G33="","",E33*G33) | I33: RS Components TR | J33: https://tr.rsdelivers.com/product/rs-pro//rs-pro-duz-tespit-pimi-cap-3mm-20mm-celik/0270568 | K33: Teklif | L33: hayır | M33: Fiyat görülmedi. Alt.: Norelem/KIPP TR teklif, Amazon.com.tr ilanları (açılmadı).
A34: 33 | B34: 3 Islak istasyon | C34: PP kapaklı tank | D34: IKEA 365+ 4,2 L, 21x15x23 cm, kap+kapak PP | E34: 4 | F34: adet | G34: 329 | H34: =IF(G34="","",E34*G34) | I34: IKEA | J34: https://www.ikea.com.tr/urun/ikea-365--plastik-4-2-lt-kapakli-plastik-saklama-kabi-59276822 | K34: Stokta | L34: evet | M34: Banyo / aşındırma / sökme / durulama. 100 mm kart dik sığar.
A35: 34 | B35: 3 Islak istasyon | C35: Isıtıcı | D35: Newa Therm 50 W, cam tüp, termostatlı | E35: 1 | F35: adet | G35: 1554.08 | H35: =IF(G35="","",E35*G35) | I35: Evcilal | J35: https://www.evcilal.com/urun/newa-therm-50-w | K35: Stokta | L35: evet | M35: Akvaryum termostatı ~32–34 °C'de keser (tipik): 40–50 °C için ESP32 + SSR ile sür. Titanyum küçük ısıtıcı TR'de yok.
A36: 35 | B36: 3 Islak istasyon | C36: Hava pompası | D36: Sobo SB-666A, çift çıkış, 5 W, 2x4 L/dk | E36: 1 | F36: adet | G36: 375 | H36: =IF(G36="","",E36*G36) | I36: Mixpet | J36: https://www.mixpet.com.tr/sobo-cift-cikisli-akvaryum-hava-motoru-5w-2x4lt/dak-sb-666a | K36: Stokta | L36: evet | M36: Pompayı sıvı seviyesinin üstüne koy.
A37: 36 | B37: 3 Islak istasyon | C37: Silikon hava hortumu | D37: 4x6 mm, 5 m | E37: 1 | F37: adet | G37: 75 | H37: =IF(G37="","",E37*G37) | I37: Badem Akvaryum | J37: https://www.bademakvaryum.com/akvaryum-hava-hortumu-silikonlu-5-metre-1199 | K37: Stokta | L37: evet
A38: 37 | B38: 3 Islak istasyon | C38: Çekvalf | D38: 4/6 mm | E38: 2 | F38: adet | G38: 30 | H38: =IF(G38="","",E38*G38) | I38: Badem Akvaryum | J38: https://www.bademakvaryum.com/akvaryum-cek-valf-hava-hortum-aparati-385 | K38: Stokta | L38: evet | M38: Şart: asit pompaya geri emilmesin.
A39: 38 | B39: 3 Islak istasyon | C39: Hava taşı | D39: Düz, 15 cm | E39: 1 | F39: adet | G39: 70 | H39: =IF(G39="","",E39*G39) | I39: Badem Akvaryum | J39: https://www.bademakvaryum.com/akvaryum-hava-tasi-duz-15-cm-630 | K39: Stokta | L39: evet | M39: Seramik/mineral taş asitte dağılabilir: en sağlamı delikli PP boru.
A40: 39 | B40: 3 Islak istasyon | C40: ORP elektrodu (BNC) | D40: SEKO, ±1000 mV, 60 °C, epoksi gövde, 1,5 m kablo | E40: 1 | F40: adet | G40: 8146.67 | H40: =IF(G40="","",E40*G40) | I40: Havuzdan.com | J40: https://www.havuzdan.com/urun/seko-dozaj-pompasi-orp-elektrodu-1-5-mt-kabloluwf-sk | K40: Sayfada yazmıyor | L40: evet | M40: Alt.: ISOLAB ORP probu 7.225,44 TL (interlab); EMEC ERHL 9.576 TL (sentezlab). Ucuz BNC problar yurt dışından.
...

Sheet Alternatifler
A1: Modül | B1: Kalem | C1: Özellik | D1: Fiyat (TL, KDV dahil) | E1: Satıcı | F1: Link | G1: Stok | H1: Not
A2: 1 Pozlama | B2: Aptus 10.3" 8K mono LCD | C2: DBM103M8K01, 7680x4320, ~30 µm, ~228x128 mm (hesap), MIPI 50 pin | E2: Aptus Display | F2: https://www.aptusdisplay.com/products/10-3-inch-8k-7680x4320-mipi-50pin-mono-lcd-screen | G2: Teklif | H2: Daha büyük kartlar (150x100 desen) gerekirse.
A3: 1 Pozlama | B3: Phrozen Sonic Mighty 4K LCD (yedek parça) | C3: 9.3", 3840x2400, ~52 µm | D3: 11280 | E3: 3Dream | F3: https://store.3dream.com.tr/products/phrozen-lcd-ekran | G3: Stokta | H3: Aptus numunesi gelene kadar deney için; ürüne girmez.
A4: 1 Pozlama | B4: Waveshare ESP32-P4-NANO | C4: MIPI-DSI 2 hat, 32 MB PSRAM | D4: 2400 | E4: Motorobit | F4: https://www.motorobit.com/esp32-p4-nano-yuksek-performansli-gelistirme-karti | G4: Stokta | H4: Aptus panelleri (8K / çift MIPI) için yetersiz; HDMI kartı + Raspberry Pi yolu seçildi.
A5: 1 Pozlama | B5: Raspberry Pi CM5 2 GB / 16 GB + IO Board | C5: Ürün için gömülü HDMI kaynağı | D5: 7488.84 | E5: Robotistan | F5: https://www.robotistan.com/raspberry-pi-compute-module-cm5002016 | G5: Stokta | H5: CM5 6.228,05 + IO Board 1.260,79 (https://www.robotistan.com/raspberry-pi-compute-module-5-ioboard).
A6: 1 Pozlama | B6: Soğutucu + fan 80x80x54 | C6: İşlemci soğutucusu, 12 V fan | D6: 390 | E6: Motorobit | F6: https://www.motorobit.com/80x80x54mm-sogutuculu-fan-islemci-fani | G6: Stokta | H6: COB seti yerine alternatif.
A7: 2 CNC portal | B7: Hazır CNC3018 kit (lazerli) | C7: 300x180x45 mm, 775 mil (ER11 değil), düz mil + T-vida, GRBL | D7: 26700 | E7: Motorobit | F7: https://www.motorobit.com/cnc3018-15000mw-lazerli-cnc-makinesi-kesim-tezga | G7: Stokta (8) | H7: v0 hızlı deneme. ±0,1 mm: ±0,02 hedefini tutmaz. Aynı kit Robotistan 28.307,95 TL.
A8: 2 CNC portal | B8: Hazır CNC3018 PRO MAX | C8: 500 W φ52 mil 48 V, limit switch + Z probu + acil stop dahil | D8: 50100 | E8: Motorobit | F8: https://www.motorobit.com/cnc3018-pro-max-15000mw-lazerli-cnc-makinesi-kesim-tezgahi | G8: Stokta (5) | H8: v0 için daha uygun kit; sürücüler A4988, T-vida.
A9: 2 CNC portal | B9: Hazır DRNC 3025 | C9: 30x25 cm, bilyalı vida + 15 mm ray, 600 W ER11 mil | D9: 104611.61 | E9: Direnc.net | F9: https://www.direnc.net/drnc-3025-masaustu-cnc-ve-lazer-makinesi | G9: Stokta (1) | H9: Hedef mimariye en yakın hazır makine.
A10: 2 CNC portal | B10: CNC3018 lazersiz (en ucuz) | C10: Temel 3018 | D10: 9899.86 | E10: Robotistan | F10: https://www.robotistan.com/cnc3018-masaustu-cnc-makinesi | G10: Stokta yok
A11: 2 CNC portal | B11: MGN12 ray + MGN12H | C11: 400 mm set | D11: 1080 | E11: Motorobit | F11: https://www.motorobit.com/mgn12-lineer-ray-kizak-400mm-mgn12h-bilyali-rulm | G11: Stokta (14) | H11: HGR15 yerine hafif seçenek.
A12: 2 CNC portal | B12: SFU1605 vidalı mil | C12: SCR1605, metre fiyatı, uç işleme yok | D12: 1575.35 | E12: cnc-marketi | F12: https://www.cnc-marketi.com/urun/vidali-mil-1605-vidali-mil | G12: Stokta (267 m) | H12: Somun ayrı 573,02 TL (stokta yok).
A13: 2 CNC portal | B13: TMC2209 V2.0 | C13: 1,7 A RMS, 4,75–29 V | D13: 390 | E13: Motorobit | F13: https://www.motorobit.com/tmc2209-v20-step-motor-surucusu | G13: Stokta (25) | H13: TMC5160 yerine ucuz (3 adette ~3.650 TL düşer).
A14: 1 Pozlama | B14: Elegoo Saturn 2 / 8K LCD | C14: 10", 7680x4320, ~28,5 µm | D14: 4700 | E14: 3Dream | F14: https://store.3dream.com.tr/products/elegoo-lcd-ekran-saturn-8k-10-8k-saturn-2 | G14: Stokta | H14: 150x100'ü kapsayan en ucuz mono LCD; ESP32-P4 ile sürmek zor.
A15: 1 Pozlama | B15: Anycubic M7 Pro anakartı | C15: Yazıcının kendi LCD/ışık denetleyicisi | D15: 7050 | E15: 3Dream | F15: https://store.3dream.com.tr/collections/yedek-parca-anycubic | G15: Stokta | H15: İlk deneyde M7 Pro LCD + ışık + Fresnel'i kendi kartıyla sürme yolu (kapalı yazılım, yalnız deney).
A16: 1 Pozlama | B16: Waveshare ESP32-P4-Pico | C16: 32 MB PSRAM, MIPI DSI/CSI | D16: 1646.73 | E16: Robotistan | F16: https://www.robotistan.com/waveshare-esp32p4pico-riscv-gelistirme-karti | G16: Stokta
A17: 1 Pozlama | B17: 3 W UV power LED | C17: 395–400 nm, 600–700 mA | D17: 87.95 | E17: Roboshop | F17: https://www.roboshop.com.tr/3w-power-led-uv-mor-395-400nm | G17: Stokta | H17: Kendin-yap dizi (10–16 adet). 405 değil ama Positiv 20 için uygun.
A18: 4 Hot plate | B18: Hazır ön ısıtıcı Sunline 958 | C18: 130x130 mm, 600 W, 50–400 °C | D18: 13145.64 | E18: Robotistan | F18: https://www.robotistan.com/sunline-958-havya-istasyonu | G18: Stokta (5) | H18: 150x100 kart 20 mm taşar. Direnc 13.521,05 TL.
A19: 4 Hot plate | B19: Nofaner 200x200 hot plate | C19: 220 V, dijital | E19: Amazon.com.tr | F19: https://www.amazon.com.tr/Nofaner-istasyonu-elektrikli-lehimleme-d%C3%BCzenlemesi/dp/B0B7BG89KB | G19: ? | H19: TR'de bulunan tek 200x200; doğrulanamadı.
A20: 3 Islak istasyon | B20: Perklorür (FeCl3) sıvı | C20: 1 kg | D20: 125 | E20: Kimyacınız | F20: https://www.kimyaciniz.com/demir-3-klorur-sivi-1-kg | G20: Stokta | H20: Kupri klorür yerine tek kullanımlık aşındırıcı.
A21: 3 Islak istasyon | B21: Sodyum persülfat | C21: 1 kg | D21: 584.67 | E21: Kimya Depom | F21: https://www.kimyadepom.com/urun/sodyum-persulfat-25-kg-torba | G21: Sipariş verilebilir | H21: Temiz, şeffaf aşındırıcı.
A22: 3 Islak istasyon | B22: ISOLAB ORP probu | C22: Ölçüm cihazları için | D22: 7225.44 | E22: Interlab | F22: https://shop.interlab.com.tr/urun/orp-probu-olcum-cihazlari-icin | G22: ? | H22: SEKO'dan ucuz.
A23: 3 Islak istasyon | B23: UV lehim maskesi (yeşil) | C23: Mechanic MT-UVH900, 10 cc | E23: Hepsiburada | F23: https://www.hepsiburada.com/mechanic-mt-uvh900-ly-uv-isikla-sertlesen-solder-mask-devre-yalitim-boyasi-lehim-maskesi-10cc-yesil-pm-HBC0000FVNW47 | G23: ? | H23: v2 lehim maskesi pozlaması için.
A24: 3 Islak istasyon | B24: Dry film (negatif) | C24: 30 cm x 5 m | E24: n11 | F24: https://www.n11.com/urun/devre-uretim-icin-kuru-film-fotoresist-carsaf-duzleme-islemi-30cm-x-5m-pcb-podiksiyatler-kuru-film-dogruluk-deneyimli-film-79346576 | G24: ? | H24: Arama özetinde ~1.191 TL; çoğu yurt dışından.

Sheet Yurt dışı
A1: Modül | B1: Kalem | C1: Ne için | D1: Nereden
A2: 1 Pozlama | B2: Aptus 6.6" 4K mono LCD + HDMI→MIPI kartı | C2: Ürün paneli (numune 2 adet). | D2: Aptus Display, Shenzhen: info@aptusdisplay.com (teklif/numune).
A3: 1 Pozlama | B3: HDMI sürücü kartlı mono LCD kiti (2K/4K) | C3: İlk ışık motoru deneyi; panel arayüzünü çözmeden pozlama. | D3: AliExpress: "mono LCD 4K HDMI driver board" (mono olduğunu kontrol et, çoğu ilan RGB).
A4: 1 Pozlama | B4: 405 nm COB LED 10–50 W | C4: Kendi ışık motoru tasarımı. | D4: AliExpress / LED üreticisi; TR'de yalnız 395–400 nm 3 W LED var.
A5: 1 Pozlama | B5: Mean Well LDD-1000H / LDD-1500H | C5: PWM ile kısılabilir sabit akım LED sürücü (ürün sınıfı). | D5: Mouser / Digikey / AliExpress.
A6: 1 Pozlama | B6: UV engelleyici turuncu akrilik / reçine yazıcı kapağı | C6: Kabin penceresi, 405 nm kesmesi garanti. | D6: AliExpress / yazıcı yedek parçası.
A7: 3 Islak istasyon | B7: DFRobot Gravity SEN0165 ORP kartı | C7: Hazır ORP yükselticisi (±2000 mV). | D7: AB ~€98 (opencircuit.shop) ya da DFRobot; TR alternatifi ADS1115 + op-amp.
A8: 3 Islak istasyon | B8: Küçük titanyum / PTFE ısıtıcı | C8: Asitte güvenli 50–100 W ısıtıcı. | D8: AliExpress; ya da yerli rezistans üreticisinden teklif (aliserezistans, isielektrik).
A9: 2 CNC portal | B9: Ön yüklü çift somun ya da C5 taşlanmış bilyalı vida | C9: ±0,02 mm tekrarlanabilirlik. | D9: Önce Mermak / Rulmansepetim'e sor; yoksa Hiwin/TBI distribütörü.

Sheet Uyarılar
A1: # | B1: Uyarı
A2: 1 | B2: Fiyatlar 2026-10-04'te görülen KDV dahil TL fiyatlarıdır; stok ve fiyat her gün değişir. USD bazlı satıcılar (Rulmansepetim, Meon, cnc-marketi) kurla oynar.
A3: 2 | B3: Doğrulandı = "hayır" satırları (Hepsiburada, Trendyol, n11, Amazon.com.tr, Akakçe, Koçtaş vb.) yalnız arama özetinden; siparişten önce sayfada kontrol et.
A4: 3 | B4: Fiyatı boş satırlar toplamda yok sayılır (Özet sayfasında sayısı yazar): ısıtıcı plaka, konum pimleri, turuncu akrilik, atık bidonu.
A5: 4 | B5: Kargo, gümrük, cıvata/somun, alüminyum plakalar, 3D baskı parçalar ve PCB'ler dahil değil.
A6: 5 | B6: Kimyasallar: bazı satıcılar şahıslara satmıyor (Rokim/laboratuvar siteleri, Kimyacınız aseton), Kimyacınız HCl'yi kargolamıyor. H2O2 ADR 5.1, HCl ADR 8: kargo reddedebilir. Ticari aşamada şirket faturasıyla al.
A7: 6 | B7: Mono LCD: Aptus (üretici) panelleri HDMI→MIPI kartıyla Raspberry Pi'den sürülür; ESP32-P4 bu panellere yetmez (8K veri hızı, çift MIPI). Fiyat/MOQ/datasheet Aptus teklifiyle netleşir; teklif gelene kadar pozlama toplamı eksik.
A8: 7 | B8: CNC: hazır 3018 kitleri ±0,1 mm; hedef ±0,02 mm için ray + bilyalı vida (bu BOM) ve düşük salgılı mil gerekir. Kitlerle gelen GRBL GPL lisanslı: ürüne girmez.
A9: 8 | B9: Akvaryum ısıtıcı termostatı ~32–34 °C'de keser; 40–50 °C aşındırma için ESP32 + SSR ile sür ve aşırı sıcaklık kesicisi ekle.
A10: 9 | B10: Bakırlı atık kanalizasyona dökülmez. HCl buharı metalleri paslandırır: ıslak istasyon CNC ve elektronikten ayrı, havalandırmalı kabinde.
A11: 10 | B11: Robotistan sayfalarında gizli "Tükendi" etiketi var; stok, sayfanın ürün verisinden (stok adedi) okundu.
